<mujoco model="3r_planar_pen_robot">
  <compiler angle="degree" coordinate="local" autolimits="true"/>

  <option timestep="0.002" integrator="RK4" gravity="0 0 -9.81"/>

  <default>
    <joint damping="0.5" armature="0.01"/>
    <geom condim="3" friction="0.8 0.1 0.1"/>
    <default class="link">
      <geom type="capsule" size="0.018" rgba="0.12 0.43 0.92 1"/>
    </default>
    <default class="raised_link">
      <geom type="capsule" size="0.016" rgba="0.95 0.56 0.08 1"/>
    </default>
  </default>

  <asset>
    <material name="white_surface" rgba="1 1 1 1"/>
    <material name="pen_black" rgba="0.02 0.025 0.03 1"/>
    <material name="joint_dark" rgba="0.12 0.16 0.22 1"/>
  </asset>

  <worldbody>
    <light name="key_light" pos="0 -0.6 1.2" dir="0 0.4 -1" diffuse="0.9 0.9 0.9"/>
    <camera name="top_view" pos="0.2 0 1.2" xyaxes="0 1 0 -1 0 0"/>
    <camera name="side_view" pos="0.25 -0.8 0.25" xyaxes="1 0 0 0 0 1"/>

    <geom name="writing_surface" type="plane" pos="0 0 0" size="0.45 0.45 0.01" material="white_surface"/>

    <body name="base" pos="0 0 0.055">
      <geom name="base_plate" type="cylinder" size="0.045 0.012" material="joint_dark"/>

      <body name="link1" pos="0 0 0">
        <joint name="joint1" type="hinge" axis="0 0 1" range="-180 180"/>
        <geom name="link1_bar" class="link" fromto="0 0 0 0.14 0 0"/>
        <geom name="joint1_hub" type="sphere" size="0.028" material="joint_dark"/>

        <body name="link2_bridge" pos="0.14 0 0">
          <joint name="joint2" type="hinge" axis="0 0 1" range="-160 160"/>
          <geom name="joint2_hub" type="sphere" size="0.024" material="joint_dark"/>
          <geom name="link2_riser_up" class="raised_link" fromto="0 0 0 0 0 0.055"/>
          <geom name="link2_raised_bar" class="raised_link" fromto="0 0 0.055 0.11 0 0.055"/>
          <geom name="link2_riser_down" class="raised_link" fromto="0.11 0 0.055 0.11 0 0"/>

          <body name="link3" pos="0.11 0 0">
            <joint name="joint3" type="hinge" axis="0 0 1" range="-180 180"/>
            <geom name="joint3_hub" type="sphere" size="0.024" material="joint_dark"/>
            <geom name="link3_bar" class="link" fromto="0 0 0 0.125 0 0"/>

            <body name="pen" pos="0.125 0 0">
              <geom name="pen_body" type="capsule" fromto="0 0 0 0 0 -0.049" size="0.006" material="pen_black"/>
              <site name="pen_tip" pos="0 0 -0.055" size="0.006" rgba="0 0 0 1"/>
            </body>
          </body>
        </body>
      </body>
    </body>
  </worldbody>

  <actuator>
    <motor name="joint1_motor" joint="joint1" gear="0.2" ctrllimited="true" ctrlrange="-1 1"/>
    <motor name="joint2_motor" joint="joint2" gear="0.2" ctrllimited="true" ctrlrange="-1 1"/>
    <motor name="joint3_motor" joint="joint3" gear="0.2" ctrllimited="true" ctrlrange="-1 1"/>
  </actuator>

  <keyframe>
    <key name="writing_pose" qpos="35 -50 45"/>
  </keyframe>
</mujoco>
